Workbook

Sheet BALEREJO  
A1: DATA BALITA MENDAPAT BANTUAN SUSU PKMK
A2: DESA BALEREJO
A4: No | B4: NIK | C4: Nama | D4: JK | E4: Tgl Lahir | F4: Nama Ortu | G4: Tanggal Pemberian | H4: BB | I4: TB | J4: Z-Score BB/U | K4: BB/U | L4: Z-Score TB/U | M4: TB/U | N4: Z-Score BB/TB | O4: BB/TB | P4: Tanggal Pemberian | Q4: BB | R4: TB | S4: Z-Score BB/U | T4: BB/U | U4: Z-Score TB/U | V4: TB/U | W4: Z-Score BB/TB | X4: BB/TB | Y4: Tanggal Pemberian | Z4: BB | AA4: TB | AB4: Z-Score BB/U | AC4: BB/U | AD4: Z-Score TB/U | AE4: TB/U | AF4: Z-Score BB/TB | AG4: BB/TB | AH4: Tanggal Pemberian | AI4: BB | AJ4: TB | AK4: Z-Score BB/U | AL4: BB/U | AM4: Z-Score TB/U | AN4: TB/U | AO4: Z-Score BB/TB | AP4: BB/TB | AQ4: Tanggal Pemberian | AR4: BB | AS4: TB | AT4: Z-Score BB/U | AU4: BB/U | AV4: Z-Score TB/U | AW4: TB/U | AX4: Z-Score BB/TB | AY4: BB/TB | AZ4: Tanggal Pemberian | BA4: BB | BB4: TB | BC4: Z-Score BB/U | BD4: BB/U | BE4: Z-Score TB/U | BF4: TB/U | BG4: Z-Score BB/TB | BH4: BB/TB
A5: 1 | B5: 330813561120001 | C5: ALINA IBNATU KHOLIFAH | D5: P | E5: 44516 | F5: UMI KHANIFA/SLAMET CHOLIDIN | G5: 45424 | H5: 11.1 | I5: 84.2 | P5: 14/12/2024 | Q5: 11.3 | R5: 85.3 | Y5: 45931 | Z5: 11.7 | AA5: 86.2 | AH5: 24/1/2025 | AI5: 11.9 | AJ5: 87.8 | AQ5: 45871 | AR5: 12 | AS5: 85.9 | AT5: (-1.4) | AU5: Normal | AV5: (-2.78) | AW5: Pendek | AX5: (-0.36) | AY5: Normal | AZ5: 21/2/2025 | BA5: 12.3 | BB5: 88.5 | BC5: (-1.20) | BD5: Normal | BE5: (-2.12) | BF5: Pendek | BG5: 0.02 | BH5: Normal
A6: 2 | B6: 3308401510216375 | C6: MUHAMMAD KHOIRUR IVAN | D6: L | E6: 44484 | F6: MUHAMMAD SUTOPO/SITI ZAITUN | G6: 45424 | H6: 11.78 | I6: 88.7 | P6: 14/12/2024 | Q6: 12.3 | R6: 88.6 | Y6: 45931 | Z6: 12.8 | AA6: 89.7 | AH6: 24/1/2025 | AI6: 12.8 | AJ6: 90.1 | AQ6: 45871 | AR6: 13.3 | AS6: 90.8 | AT6: (-0.88) | AU6: Normal | AV6: (-1.84) | AW6: Normal | AX6: 0.21 | AY6: Normal | AZ6: 21/2/2025 | BA6: 13.4 | BB6: 91.2 | BC6: -0.82 | BD6: Normal | BE6: 1.74 | BF6: Normal | BG6: 0.22 | BH6: Normal
A7: 3 | B7: 3308131606230001 | C7: BISMA ENGGAR PANGESTU | D7: L | E7: 45103 | F7: MUHLISON/PUJI ASTUTIK | G7: 45424 | H7: 8.35 | I7: 73.2 | P7: 14/12/2024 | Q7: 8.1 | R7: 72 | Y7: 45931 | Z7: 8.8 | AA7: 73.4 | AH7: 24/1/2025 | AI7: 8.8 | AJ7: 74.4 | AQ7: 45871 | AR7: 8.8 | AS7: 76.1 | AT7: -4.15 | AU7: BB sgt kurang | AV7: -5.68 | AW7: Sgt Pendek | AX7: -1.39 | AY7: Normal | AZ7: 21/2/2025 | BA7: 9.1 | BB7: 76.1 | BC7: -0.98 | BD7: Normal | BE7: -5.68 | BF7: Sgt Pendek | BG7: 0.98 | BH7: Normal
A8: 4 | B8: 3308402109202558 | C8: DWI KAMILIA ANDINI | D8: L | E8: 44095 | F8: untung suparman N/asrifah | G8: 45424 | H8: 10.5 | I8: 89.1 | P8: 14/12/2024 | Q8: 10.7 | R8: 90.4 | Y8: 45931 | Z8: 10.3 | AA8: 90.7 | AH8: 24/1/2025 | AI8: 10.9 | AJ8: 90.8 | AQ8: 45871 | AR8: 11 | AS8: 90.8 | AT8: -2.13 | AU8: BB Kurang | AV8: -1.56 | AW8: Normal | AX8: -1.79 | AY8: Normal | AZ8: 21/2/2025
A9: 5 | B9: 3308406210218640 | C9: NAHLA SYAKIRA FARIZA | D9: P | E9: 44308 | F9: A.FATIHIN/ PUJI LESTARI | G9: 45424 | H9: 12.3 | I9: 90.3 | P9: 14/12/2024 | Q9: 11.9 | R9: 91 | Y9: 45931 | Z9: 12.2 | AA9: 91.2 | AH9: 24/1/2025 | AQ9: 45871 | AR9: 12 | AS9: 92 | AT9: -2.18 | AU9: BB Kurang | AV9: -2.44 | AW9: Pendek | AX9: -1.04 | AY9: Normal | AZ9: 21/2/2025
A10: 6 | B10: 3308405205218322 | C10: MANDA QEIZA SHAFANA | D10: P | E10: 44328 | F10: Siti Chosiyah/Zaenal arifin | G10: 45424 | H10: 10.8 | I10: 88 | P10: 14/12/2024 | Y10: 45931 | Z10: 11.3 | AA10: 89.1 | AH10: 24/1/2025 | AI10: 10.7 | AJ10: 89.9 | AQ10: 45871 | AR10: 10.8 | AS10: 89.3 | AT10: -3.08 | AU10: BB sgt kurang | AV10: -3.07 | AW10: Sgt Pendek | AX10: -1.66 | AY10: Normal | AZ10: 21/2/2025
A11: 7 | B11: 3308400406215848 | C11: M DAMAR BRAMANTYO | D11: L | E11: 44351 | F11: via syafitri N/ahmad syarif | G11: 45424 | H11: 11.6 | I11: 92.6 | P11: 14/12/2024 | Q11: 12.2 | R11: 92.1 | Y11: 45931 | Z11: 12 | AA11: 93.7 | AH11: 24/1/2025 | AI11: 12.7 | AJ11: 93.7 | AQ11: 45871 | AR11: 12.6 | AS11: 93.9 | AT11: -0.85 | AU11: Normal | AV11: -1.79 | AW11: Normal | AX11: -0.63 | AY11: Normal | AZ11: 21/2/2025
A12: 8 | B12: 3308405307218036 | C12: ANNIDA IZZATULMARWA A | D12: P | E12: 44390 | F12: ERFIN MIF'ATUS SOLIKHAH N/AHMAD ZAENAL ABIDIN | G12: 45424 | H12: 11 | I12: 85.4 | P12: 14/12/2024 | Y12: 45931 | AH12: 24/1/2025
A13: 9 | B13: 3308402604228405 | C13: DZAKA RIZKI RAMADHAN | D13: L | E13: 44677 | F13: Makmuri/titik hartanti | G13: 45424 | H13: 10.4 | I13: 86.2 | P13: 14/12/2024 | Q13: 10.9 | R13: 85.9 | Y13: 45931 | Z13: 11 | AA13: 87 | AH13: 24/1/2025 | AI13: 10.8 | AJ13: 87 | AQ13: 45871 | AZ13: 21/2/2025
A14: 10 | B14: 3308401307227334 | C14: QOBA QOUSAINI AU ADNA | D14: L | E14: 44755 | F14: Wahyu F/chamdan abdulloh | G14: 45424 | H14: 9.9 | I14: 83.5 | P14: 14/12/2024 | Y14: 45931 | Z14: 10.1 | AA14: 84.8 | AH14: 24/1/2025 | AI14: 10 | AJ14: 85 | AQ14: 45871 | AR14: 9.5 | AS14: 86 | AT14: -2.84 | AU14: BB Kurang | AV14: -1.98 | AW14: Normal | AX14: -2.38 | AY14: Normal | AZ14: 21/2/2025 | BA14: 9.6 | BB14: 86.5 | BC14: -0.79 | BD14: Normal | BE14: 1.58 | BF14: Normal | BG14: -2.33 | BH14: GZ Kurang
A15: 11 | B15: 3308405811227473 | C15: ANANDA SAQUENA ARASELY | D15: P | E15: 44883 | F15: Slamet TOBI'IN/marwanti | G15: 45424 | H15: 8.9 | I15: 79.6 | P15: 14/12/2024 | Y15: 45931 | AH15: 24/1/2025
A16: 12 | B16: 33081341 | C16: NUMMA HADIYA Q | D16: P | E16: 45360 | F16: Alvia rani | G16: 45424 | H16: 8.1 | I16: 67.4 | P16: 14/12/2024 | Y16: 45931 | Z16: 8.56 | AA16: 69.6 | AH16: 24/1/2025 | AI16: 8.84 | AJ16: 70.6 | AQ16: 45871 | AR16: 9.1 | AS16: 71.3 | AT16: 1.8 | AU16: Normal | AV16: 1.8 | AW16: Normal | AX16: 1.29 | AY16: Normal | AZ16: 21/2/2025 | BA16: 9.1 | BB16: 71.8 | BC16: 1.46 | BD16: Normal | BE16: 2.02 | BF16: Pendek | BG16: 1.46 | BH16: Normal
A17: 13 | B17: 3308132603240001 | C17: ALFARIZKI SYABIL AHMAD | D17: L | E17: 45377 | F17: AHMAD SUKRON /NURUL SAPUTRI | G17: 45424 | H17: 7.43 | I17: 68.3 | P17: 14/12/2024 | Q17: 7.96 | R17: 67.4 | Y17: 45931 | AH17: 24/1/2025 | AQ17: 45871 | AZ17: 21/2/2025
A18: 14 | B18: 3308134308200003 | C18: HAFSYA KAMILATUNNISA | D18: P | E18: 44046 | F18: SLAMET KHOIRI/IIN NAFIROH | G18: 45424 | H18: 13.5 | I18: 90 | P18: 14/12/2024 | Q18: 13.3 | R18: 89 | Y18: 45931 | Z18: 14.2 | AA18: 91.2 | AH18: 24/1/2025 | AQ18: 45871 | AR18: 14.15 | AS18: 91 | AT18: 2.38 | AU18: BB Kurang | AV18: 1.06 | AW18: Normal | AX18: 1.06 | AY18: Normal | AZ18: 21/2/2025
A19: 15 | B19: 3308136804230000 | C19: UZMA AZKIYA LIYANA | D19: L | E19: 43898 | F19: SOLICHAN ASNAWI | G19: 45424 | H19: 9.22 | I19: 76.1 | P19: 14/12/2024 | Y19: 45931 | Z19: 9.54 | AA19: 77.7 | AH19: 24/1/2025 | AI19: 9.75 | AJ19: 77.7 | AQ19: 45871 | AR19: 9.8 | AS19: 78 | AT19: -4.32 | AU19: BB sgt kurang | AV19: -6.58 | AW19: Sgt Pendek | AX19: -0.04 | AY19: Normal | AZ19: 21/2/2025 | BA19: 9.9 | BB19: 78.4 | BC19: -4.26 | BD19: BB sgt kurang | BE19: -6.49 | BF19: Sgt pendek | BG19: -0.01 | BH19: Normal
A20: 16 | B20: 3308134902230000 | C20: REFINA PUTRI | D20: P | E20: 45171 | F20: Siti Latifah | G20: 45424 | H20: 8.9 | I20: 77.6 | P20: 14/12/2024 | Q20: 9.08 | R20: 77.6 | Y20: 45931 | Z20: 9.12 | AA20: 78.1 | AH20: 24/1/2025 | AI20: 9.7 | AJ20: 80.1 | AQ20: 45871 | AR20: 9.2 | AS20: 80.5 | AT20: -0.83 | AU20: Normal | AV20: 0.03 | AW20: Normal | AX20: -1.17 | AY20: Normal | AZ20: 21/2/2025
A21: J U M L A H

Sheet NGAWONGGO
A1: DATA BALITA MENDAPAT BANTUAN SUSU PKMK
A2: DESA NGAWONGGO
A4: No | B4: NIK | C4: Nama | D4: JK | E4: Tgl Lahir | F4: Nama Ortu | G4: Alamat | H4: Usia Saat Ukur | I4: Tanggal Pemberian | J4: BB | K4: TB | L4: Z-Score BB/U | M4: BB/U | N4: Z-Score TB/U | O4: TB/U | P4: Z-Score BB/TB | Q4: BB/TB | R4: Tanggal Pemberian | S4: BB | T4: TB | U4: Z-Score BB/U | V4: BB/U | W4: Z-Score TB/U | X4: TB/U | Y4: Z-Score BB/TB | Z4: BB/TB | AA4: Tanggal Pemberian | AB4: BB | AC4: TB | AD4: Z-Score BB/U | AE4: BB/U | AF4: Z-Score TB/U | AG4: TB/U | AH4: Z-Score BB/TB | AI4: BB/TB | AJ4: Tanggal Pemberian | AK4: BB | AL4: TB | AM4: Z-Score BB/U | AN4: BB/U | AO4: Z-Score TB/U | AP4: TB/U | AQ4: Z-Score BB/TB | AR4: BB/TB | AS4: Tanggal Pemberian | AT4: BB | AU4: TB | AV4: Z-Score BB/U | AW4: BB/U | AX4: Z-Score TB/U | AY4: TB/U | AZ4: Z-Score BB/TB | BA4: BB/TB | BB4: Kenaikan BB | BC4: Kenaikan TB
A5: 1 | B5: 3308400603225330 | C5: BASTIAN | D5: L | E5: 44626 | F5: SURTIYAH/IKHSANUDIN | G5: PENGKOL | H5: 2 Tahun - 8 Bulan - 19 Hari | I5: 45455 | J5: 12.4 | K5: 86 | R5: 14/12/2024
A6: 2 | B6: 3308401703225460 | C6: IQBAL BAGAS PUTRA | D6: L | E6: 44637 | F6: PUJI LESTARI/SRI ALIMAH | G6: PENGKOL | H6: 2 Tahun - 7 Bulan - 17 Hari | I6: 45455 | J6: 9.9 | K6: 80 | R6: 14/12/2024 | S6: 9.9 | T6: 80.2 | AA6: 45931 | AB6: 10.1 | AC6: 81.7 | AJ6: 24/1/2025 | AK6: 10.3 | AL6: 81.2 | AS6: 45871 | AT6: 10.3 | AU6: 81.8 | AV6: -2.7 | AW6: BB Kurang | AX6: -3.76 | AY6: Sangat pendek | AZ6: -2.7 | BA6: Gz sangat kurang | BB6: =AT6-S6 -> 0.4 | BC6: =AU6-T6 -> 1.6
A7: 3 | B7: 3308135912220000 | C7: KINAN PINARING DEEPA | D7: P | E7: 44914 | F7: KUMIYATI/RINT0 | G7: PENGKOL | H7: 1 Tahun - 11 Bulan - 4 Hari | I7: 45455 | J7: 7.92 | K7: 79.5 | R7: 14/12/2024 | S7: 8.7 | T7: 79.2 | AA7: 45931 | AB7: 8.3 | AC7: 79.3 | AJ7: 24/1/2025 | AK7: 8.7 | AL7: 79.3 | AS7: 45871 | AT7: 9.1 | AU7: 79 | AV7: -3.36 | AW7: BB Sangat Kurang | AX7: -4.11 | AY7: Sangat pendek | AZ7: -1.11 | BA7: Normal | BB7: =AT7-S7 -> 0.4 | BC7: =AU7-T7 -> -0.2
A8: 4 | B8: 3308401507206210 | C8: AHMAD REZI | D8: L | E8: 44027 | F8: SOLIAH/WALMIN | G8: PENGKOL | H8: 4 Tahun - 4 Bulan - 9 Hari | I8: 45455 | J8: 13.7 | K8: 94.8 | R8: 14/12/2024 | S8: 13.9 | T8: 94.6 | AA8: 45931 | AC8: 95.2 | AJ8: 24/1/2025 | AK8: 13.9 | AL8: 94.9 | AS8: 45871 | BB8: =AK8-S8 -> 0 | BC8: =AL8-T8 -> 0.3
A9: 5 | B9: 3308133103200000 | C9: LINTANG KHYAR ADYA PURNAMA | D9: L | E9: 43921 | F9: DEWI RATNASARI/SARIYO AMAN | G9: GUNUNG MALANG | H9: 4 Tahun - 7 Bulan - 13 Hari | I9: 45455 | J9: 12.1 | K9: 91.5 | R9: 14/12/2024 | S9: 12.4 | T9: 92.1 | AA9: 45931 | AB9: 12.6 | AC9: 92.3 | AJ9: 24/1/2025 | AK9: 12.8 | AL9: 93 | AS9: 45871 | AT9: 12.5 | AU9: 93.5 | AV9: -2.88 | AW9: BB Kurang | AX9: -3.5 | AY9: Sangat pendek | AZ9: -1.16 | BA9: Normal | BB9: =AT9-S9 -> 0.1 | BC9: =AU9-T9 -> 1.4
A10: 6 | B10: 3308134301210000 | C10: JIHAN ZIA ALMAHYRA | D10: P | E10: 44199 | F10: TIS'A NUROHMATUL A/ROHMADI | G10: GUNUNG MALANG | H10: 3 Tahun - 10 Bulan - 9 Hari | I10: 45455 | J10: 11.3 | K10: 88.2 | R10: 14/12/2024 | S10: 11.5 | T10: 88 | AA10: 45931 | AB10: 11.7 | AC10: 89.7 | AJ10: 24/1/2025 | AK10: 11.3 | AL10: 89.8 | AS10: 45871 | BC10: =AL10-T10 -> 1.8
A11: 7 | B11: 3308402608216500 | C11: ANANDA ALWI AR-RIZQI | D11: L | E11: 44434 | F11: ASMIYATUN/MUKOHIR | G11: GUNUNG MALANG | H11: 3 Tahun - 2 Bulan - 18 Hari | I11: 45455 | J11: 9.8 | K11: 86.9 | R11: 14/12/2024 | S11: 10.3 | T11: 87 | AA11: 45931 | AB11: 10.5 | AC11: 88.3 | AJ11: 24/1/2025 | AK11: 10.5 | AL11: 88.3 | AS11: 45871 | BB11: =AK11-S11 -> 0.2 | BC11: =AL11-T11 -> 1.3
A12: 8 | B12: 3308406909212020 | C12: ANINDYA MARWA | D12: P | E12: 44468 | F12: PUJI ASTUTI/A.SUBKHAN | G12: SEDAYU | H12: 3 Tahun - 1 Bulan - 9 Hari | I12: 45455 | J12: 11.9 | K12: 86.5 | R12: 14/12/2024 | S12: 12.1 | T12: 86.3 | AA12: 45931 | AB12: 12.6 | AC12: 87.4 | AJ12: 24/1/2025 | AK12: 12.65 | AL12: 87.5 | AS12: 45871 | AT12: 12.9 | AU12: 87.7 | AV12: -2.44 | AW12: BB Kurang | AX12: -4.52 | AY12: Sangat pendek | AZ12: 0.74 | BA12: Normal | BB12: =AT12-S12 -> 0.8 | BC12: =AU12-T12 -> 1.4
A13: 9 | B13: 3308401812202790 | C13: ABDILAH FATIR | D13: L | E13: 44183 | F13: DWI ASTUTI/MIFTAHUDIN | G13: SEDAYU | H13: 3 Tahun - 10 Bulan - 19 Hari | I13: 45455 | J13: 12.1 | K13: 93 | R13: 14/12/2024 | S13: 12.3 | T13: 93.9 | AA13: 45931 | AB13: 12.3 | AC13: 95.4 | AJ13: 24/1/2025 | AK13: 12.3 | AL13: 95.4 | AS13: 45871 | AT13: 12.6 | AU13: 96.3 | AV13: -2.82 | AW13: BB Kurang | AX13: -3.97 | AY13: Sangat pendek | AZ13: -0.58 | BA13: Normal | BB13: =AT13-S13 -> 0.3 | BC13: =AU13-T13 -> 2.4
A14: 10 | B14: 3308405210208610 | C14: SHANUM SHALIHA | D14: P | E14: 44116 | F14: USWATUN CHASANAH | G14: SEDAYU | H14: 4 Tahun - 0 Bulan - 26 Hari | I14: 45455 | J14: 11.8 | K14: 92.3 | R14: 14/12/2024 | S14: 12.57 | T14: 92.3 | AA14: 45931 | AB14: 12.2 | AC14: 93.7 | AJ14: 24/1/2025 | AK14: 12.4 | AL14: 91.4 | AS14: 45871 | AT14: 12.6 | AU14: 91.3 | AV14: -2.62 | AW14: BB Kurang | AX14: -3.76 | AY14: Sangat pendek | AZ14: -3.2 | BA14: Gz kurang | BB14: =AT14-S14 -> 0.03 | BC14: =AU14-T14 -> -1
A15: 11 | B15: 3308401404228020 | C15: M RAFIZKY ATHALLAH | D15: L | E15: 44665 | F15: TRIYAH | G15: BATURAN | H15: 2 Tahun - 6 Bulan - 25 Hari | I15: 45455 | J15: 9.8 | K15: 79.6 | R15: 14/12/2024 | S15: 9.9 | T15: 80.4 | AA15: 45931 | AB15: 10.2 | AC15: 81.3 | AJ15: 24/1/2025 | AK15: 9.9 | AS15: 45871 | BB15: =AK15-S15 -> 0 | BC15: =AC15-T15 -> 0.9
A16: 12 | B16: 3308402009205530 | C16: M.ALWI SYIHAB | D16: L | E16: 44094 | F16: IMROATUL AFIFAH/FUAD ALWI | G16: NGLARANGAN | H16: 4 Tahun - 1 Bulan - 26 Hari | I16: 45455 | J16: 11.9 | K16: 89.9 | R16: 14/12/2024 | S16: 12 | T16: 89.6 | AA16: 45931 | AB16: 12.5 | AC16: 90.7 | AJ16: 24/1/2025 | AK16: 12.5 | AL16: 90.9 | AS16: 45871 | AT16: 12.7 | AU16: 90.8 | AV16: -2.56 | AW16: BB Kurang | AX16: -3.86 | AY16: Sangat pendek | AZ16: -0.13 | BA16: Normal | BB16: =AT16-S16 -> 0.7 | BC16: =AU16-T16 -> 1.2
A17: 13 | B17: 3308400412202210 | C17: ARDIANSYAH | D17: L | E17: 44169 | F17: TAMIYAH/SUPARNO | G17: BATURAN | H17: 3 Tahun - 11 Bulan - 4 Hari | I17: 45455 | J17: 13.2 | K17: 91.8 | R17: 14/12/2024 | S17: 13 | T17: 93 | AA17: 45931 | AB17: 13.2 | AC17: 92 | AJ17: 24/1/2025 | AK17: 13.2 | AL17: 92 | AS17: 45871 | AT17: 13.6 | AU17: 93.2 | AV17: -2.22 | AW17: BB Kurang | AX17: -3.56 | AY17: Sangat pendek | AZ17: -0.03 | BA17: Normal | BB17: =AT17-S17 -> 0.6 | BC17: =AU17-T17 -> 0.2
A18: 14 | B18: 330840080520477 | C18: ASIFA PUTRI SALSABILA | D18: P | E18: 44486 | F18: DONI SUSANTI | G18: MARON | H18: 3 Tahun - 1 Bulan - 3 Hari | I18: 45455 | J18: 10.8 | K18: 84.2 | R18: 14/12/2024
A19: 15 | B19: 3308130804210000 | C19: RIZWAN FAWAS UBAIDILAH | D19: L | E19: 44294 | F19: KHAQULMUBIN/ULFIYANI | G19: KEPERING | H19: 3 Tahun - 7 Bulan - 2 Hari | I19: 45455 | J19: 12.4 | K19: 89 | R19: 14/12/2024
A20: 16 | B20: 3308400807218710 | C20: AHMAD HASAN AL FALAQ | D20: L | E20: 44385 | F20: SITI MUNDIROH/ROHMAD | G20: MARON | H20: 3 Tahun - 4 Bulan - 13 Hari | I20: 45455 | J20: 11.3 | K20: 88.8 | R20: 14/12/2024 | S20: 11.9 | T20: 89.1 | AA20: 45931 | AB20: 12.6 | AC20: 87.4 | AJ20: 24/1/2025 | AK20: 12.2 | AL20: 89.9 | AS20: 45871 | AT20: 11.5 | AU20: 91.6 | AV20: -2.48 | AW20: BB Kurang | AX20: -2.28 | AY20: Pendek | AZ20: -1.82 | BA20: Normal | BB20: =AT20-S20 -> -0.4 | BC20: =AU20-T20 -> 2.5
A21: 17 | B21: 3308400906218890 | C21: M FARHAN TANFIDHUL CHAQ | D21: L | E21: 44356 | F21: USWATUN CHASANAH | G21: MARON | H21: 3 Tahun - 5 Bulan - 12 Hari | I21: 45455 | J21: 11.6 | K21: 89.8 | R21: 14/12/2024 | S21: 11.7 | T21: 90.9 | AA21: 45931 | AB21: 11.7 | AC21: 91.3 | AJ21: 24/1/2025 | AK21: 12.1 | AL21: 92.4 | AS21: 45871 | AT21: 11.8 | AU21: 91.2 | AV21: -2.34 | AW21: BB Kurang | AX21: -2.49 | AZ21: -1.39 | BA21: Normal | BB21: =AT21-S21 -> 0.1 | BC21: =AU21-T21 -> 0.3
A22: 18 | B22: 3308134505200000 | C22: ALYSA NIKMATUR RAMADHANI | D22: P | E22: 43956 | F22: IHSANUDIN /NIA FATMAWATI | G22: KEPERING | H22: 4 Tahun - 6 Bulan - 5 Hari | I22: 45455 | J22: 12.3 | K22: 94.6 | R22: 14/12/2024 | S22: 12.6 | T22: 94.7 | AA22: 45931 | AB22: 12.6 | AC22: 95.8 | AJ22: 24/1/2025 | AK22: 13.1 | AL22: 95.8 | AS22: 45871 | AT22: 13.2 | AU22: 96.4 | AV22: -2.15 | AW22: BB Kurang | AX22: -2.52 | AZ22: -0.86 | BA22: Normal | BB22: =AT22-S22 -> 0.6 | BC22: =AU22-T22 -> 1.7
A23: 19 | B23: 3308400110217170 | C23: CHABIB NUR ROZAK | D23: L | E23: 44470 | F23: ALFIYAH | G23: NGLARANGAN | H23: 3 Tahun - 1 Bulan - 15 Hari | I23: 45455 | J23: 12.4 | K23: 89.7 | R23: 14/12/2024 | S23: 12.7 | T23: 90.3 | AA23: 45931 | AB23: 12.3 | AC23: 90.3 | AJ23: 24/1/2025 | AK23: 12.5 | AL23: 91.4 | AS23: 45871 | AT23: 13 | AU23: 90.8 | AV23: -1.24 | AW23: Normal | AX23: -2.12 | AZ23: -0.07 | BA23: Normal | BB23: =AT23-S23 -> 0.3 | BC23: =AU23-T23 -> 0.5
A24: 20 | B24: 3308401002216770 | C24: ZAKA ARFANI | D24: L | E24: 44237 | F24: WELAS ASIH/MUAR AL ARIFIN | G24: GUNUNG MALANG | H24: 3 Tahun - 9 Bulan - 2 Hari | I24: 45455 | J24: 11 | K24: 89.6 | R24: 14/12/2024 | S24: 11.1 | T24: 90 | AA24: 45931 | AB24: 11.2 | AC24: 89.7 | AJ24: 24/1/2025 | AK24: 11.7 | AL24: 9 | AS24: 45871 | AT24: 11.7 | AU24: 91.2 | AV24: -2.7 | AW24: BB Kurang | AX24: -2.93 | AZ24: -1.5 | BA24: Normal | BB24: =AT24-S24 -> 0.6 | BC24: =AU24-T24 -> 1.2
A25: 21 | B25: 3308135301220000 | C25: DELLA NESFA | D25: P | E25: 13/1/2022 | F25: MISTIYAH | G25: KEPERING | H25: 3 Tahun - 9 Bulan - 2 Hari | I25: 45455 | J25: 10.1 | K25: 81.1 | R25: 14/12/2025 | S25: 10.8 | T25: 81.8 | AA25: 45931 | AB25: 10.8 | AC25: 82.6 | AJ25: 24/1/2025 | AK25: 10.6 | AL25: 83 | AS25: 45871 | AT25: 10.6 | AU25: 83.1 | AV25: -2.3 | AW25: BB Kurang | AX25: -3.33 | AY25: Sangat pendek | AZ25: -0.35 | BA25: Normal | BB25: =AT25-S25 -> -0.2 | BC25: =AU25-T25 -> 1.3
A26: J U M L A H
I28: Mengetahui
I29: Kepala Puskesmas Kaliangkrik
I32: Ferry Ali Setiyanto, S.Kep. Ns. M.AP
I33: NIP. 198006161999031001
G35: Mengetahui
G36: Kepala Puskesmas Kaliangkrik

Sheet BALEKERTO 
A1: DATA BALITA MENDAPAT BANTUAN SUSU PKMK
A2: DESA BALEKERTO
A3: No | B3: NIK | C3: Nama | D3: JK | E3: Tgl Lahir | F3: Nama Ortu | G3: Alamat | H3: Tanggal Pemberian | I3: Berat | J3: Tinggi | K3: Jumlah Susu (Dos) | L3: Z-Score BB/U | M3: BB/U | N3: Z-Score TB/U | O3: TB/U | P3: Z-Score BB/TB | Q3: BB/TB | R3: Tanggal Pemberian | S3: Berat | T3: Tinggi | U3: Z-Score BB/U | V3: BB/U | W3: Z-Score TB/U | X3: TB/U | Y3: Z-Score BB/TB | Z3: BB/TB | AA3: Tanggal Pemberian | AB3: Berat | AC3: Tinggi | AD3: Z-Score BB/U | AE3: BB/U | AF3: Z-Score TB/U | AG3: TB/U | AH3: Z-Score BB/TB | AI3: BB/TB | AJ3: Tanggal Pemberian | AK3: Berat | AL3: Tinggi | AM3: Z-Score BB/U | AN3: BB/U | AO3: Z-Score TB/U | AP3: TB/U | AQ3: Z-Score BB/TB | AR3: BB/TB | AS3: Tanggal Pemberian | AT3: Berat | AU3: Tinggi | AV3: Kenaikan BB | AW3: Kenaikan TB | AX3: Z-Score BB/U | AY3: BB/U | AZ3: Z-Score TB/U | BA3: TB/U | BB3: Z-Score BB/TB | BC3: BB/TB | BD3: BB/U | BE3: TB/U | BF3: BB/TB | BG3: BB/U | BH3: TB/U | BI3: BB/TB
A4: 1 | B4: 3308134911200002 | C4: LUSIANA ANISA F | D4: P | E4: 44052 | F4: ANIS DEWI ADINA / DJOKO W | G4: MLILIR | H4: 45424 | I4: 11.75 | J4: 93.1 | K4: 4 | R4: 45638 | S4: 12.8 | T4: 93.5 | AA4: 45870 | AB4: 13.3 | AC4: 94.6 | AJ4: 22/1/2025 | AK4: 13.3 | AL4: 94.5 | AS4: 20/2/2025 | AT4: 13.8 | AU4: 96 | AV4: =AT4-I4 -> 2.05 | AW4: =AU4-J4 -> 2.9 | AX4: -1.61 | AY4: Normal | AZ4: -2.29 | BA4: Pendek | BB4: -0.28 | BC4: Normal | BD4: N | BE4: P | BF4: N | BG4: N | BH4: P | BI4: N
A5: 2 | B5: 3308130803210001 | C5: AHMAD AZAM WILDAN | D5: L | E5: 44263 | F5: ISMIYATI / SLAMET S | G5: BUNDISAN | H5: 45424 | I5: 14.02 | J5: 92.4 | K5: 4 | R5: 45638 | S5: 13 | T5: 92 | AA5: 45870 | AB5: 13.2 | AC5: 93.1 | AJ5: 22/1/2025 | AK5: 12.1 | AL5: 94.7 | AS5: 20/2/2025 | AT5: 13.7 | AU5: 95 | AV5: =AT5-I5 -> -0.32 | AW5: =AU5-J5 -> 2.6 | AX5: -1.36 | AY5: Normal | AZ5: -2.69 | BA5: Pendek | BB5: -0.32 | BC5: Normal | BD5: K | BE5: P | BF5: N | BG5: K | BH5: P | BI5: N
A6: 3 | B6: 3308132404210001 | C6: HAIDAR ABDUL RAZAQ | D6: L | E6: 44310 | F6: DANIK ATIKAH / SAIFUL ATIQ | G6: MLILIR | H6: 45424 | I6: 12.4 | J6: 90.5 | K6: 4 | R6: 45638 | S6: 12.8 | T6: 90.3 | AA6: 45870 | AB6: 12.6 | AC6: 91 | AJ6: 22/1/2025 | AK6: 13.1 | AL6: 91.6 | AS6: 20/2/2025 | AT6: 13.2 | AU6: 92.2 | AV6: =AT6-I6 -> 0.8 | AW6: =AU6-J6 -> 1.7 | AX6: -1.55 | AY6: Normal | AZ6: -2.43 | BA6: Pendek | BB6: 0.019 | BC6: Normal | BD6: N | BE6: P | BF6: N | BG6: N | BH6: P | BI6: N
A7: 4 | B7: 3371035706210002 | C7: KARINA PUTRI PERTIWI | D7: P | E7: 44364 | F7: NURUL ROKHIMAH / DIMAS SHOLIK | G7: MADUROSO | H7: 45424 | I7: 10.75 | J7: 88.3 | K7: 3 | R7: 45638 | S7: 11.2 | T7: 88.9 | AA7: 45870 | AB7: 11 | AC7: 88.8 | AJ7: 22/1/2025 | AK7: 11 | AL7: 89.1 | AS7: 20/2/2025 | AT7: 11.3 | AU7: 89.6 | AV7: =AT7-I7 -> 0.55 | AW7: =AU7-J7 -> 1.3 | AX7: -2.78 | AY7: BB Kurang | AZ7: -3.17 | BA7: Sgt pendek | BB7: -1.2 | BC7: Normal | BD7: K | BE7: P | BF7: N | BG7: K | BH7: P | BI7: N
A8: 5 | B8: 3308136107210002 | C8: LATIFAH PUTRI AZZAHRA | D8: P | E8: 44398 | F8: FITRI NUR ASTUTI / ERY CAHYONO | G8: MLILIR | H8: 45424 | I8: 12.3 | J8: 87 | K8: 3 | R8: 45638 | S8: 12.3 | T8: 88.2 | AA8: 45870 | AB8: 11.6 | AC8: 87.8 | AJ8: 22/1/2025 | AK8: 11.6 | AL8: 88.4 | AS8: 20/2/2025 | AT8: 12 | AU8: 89.1 | AV8: =AT8-I8 -> -0.3 | AW8: =AU8-J8 -> 2.1 | AX8: -2.29 | AY8: BB Kurang | AZ8: -3.28 | BA8: Sgt pendek | BB8: -0.39 | BC8: Normal | BD8: N | BE8: P | BF8: N | BG8: N | BH8: P | BI8: N
A9: 6 | B9: 3308136412210001 | C9: KINANTI NUR KHOLIDA | D9: P | E9: 44554 | F9: IKA SEPTIYANI / FAIZAL | G9: KIRINGAN | H9: 45424 | I9: 11.1 | J9: 86.7 | K9: 3 | R9: 45638 | S9: 12 | T9: 86.8 | AA9: 45870 | AB9: 12.1 | AC9: 86.8 | AJ9: 22/1/2025 | AK9: 12.2 | AL9: 86.9 | AS9: 20/2/2025 | AT9: 12.5 | AU9: 88.5 | AV9: =AT9-I9 -> 1.4 | AW9: =AU9-J9 -> 1.8 | AX9: -1.97 | AY9: Normal | AZ9: -3.42 | BA9: Sgt pendek | BB9: 0.21 | BC9: Normal | BD9: N | BE9: P | BF9: N | BG9: N | BH9: P | BI9: N
A10: 7 | B10: 3308130160720001 | C10: MUHAMMAD FAWWAZ | D10: L | E10: 44758 | F10: SITI FAIZAH / MUSTOFA | G10: NGAWINAN | H10: 45424 | I10: 8.25 | J10: 82.8 | K10: 3 | R10: 45638 | S10: 9.2 | T10: 83.4 | AA10: 45870 | AB10: 9.7 | AC10: 84.6 | AJ10: 22/1/2025 | AK10: 9.5 | AL10: 84.5 | AS10: 20/2/2025 | AT10: 9.3 | AU10: 85 | AV10: =AT10-I10 -> 1.05 | AW10: =AU10-J10 -> 2.2 | AX10: -3.17 | AY10: BB sgt Kurang | AZ10: -2.25 | BA10: Pendek | BB10: -2.9 | BC10: Normal | BD10: K | BE10: N | BF10: K | BG10: K | BH10: N | BI10: buruk
A11: 8 | B11: 3308132810220001 | C11: RAYYAN AZKA PRATAMA | D11: L | E11: 44862 | F11: SITI ZULAIKHAH / M ABDUL AZIZ | G11: MLILIR | H11: 45424 | I11: 9.65 | J11: 81.6 | K11: 3 | R11: 45638 | S11: 10.5 | T11: 82.6 | AA11: 45870 | AB11: 12.6 | AC11: 83.3 | AJ11: 22/1/2025 | AK11: 11 | AL11: 84.4 | AS11: 20/2/2025 | AT11: 11.4 | AU11: 85.2 | AV11: =AT11-I11 -> 1.75 | AW11: =AU11-J11 -> 3.6 | AX11: -0.34 | AY11: Normal | AZ11: -1.54 | BA11: Normal | BB11: -0.34 | BC11: Normal | BD11: N | BE11: N | BF11: N | BG11: N | BH11: N | BI11: N
A12: 9 | B12: 3308125004010005 | C12: KHOLIFATUR FAKIH M | D12: L | E12: 44975 | F12: ANIFA DAMAYANTI / A FAUZI | G12: PURWODADI | H12: 45424 | I12: 9.85 | J12: 78.2 | K12: 3 | R12: 45638 | S12: 10 | T12: 79 | AA12: 45870 | AB12: 9.8 | AC12: 79.5 | AJ12: 22/1/2025 | AK12: 9.46 | AL12: 80.1 | AS12: 20/2/2025 | AT12: 9.9 | AU12: 80.5 | AV12: =AT12-I12 -> 0.05 | AW12: =AU12-J12 -> 2.3 | AX12: -1.23 | AY12: Normal | AZ12: -1.64 | BA12: Normal | BB12: -0.49 | BC12: Normal | BD12: K | BE12: P | BF12: N | BG12: K | BH12: P | BI12: N
A13: 10 | B13: 3308130305230001 | C13: MUHAMMAD ADE ARSYAD | D13: L | E13: 45049 | F13: PATIMAH / MUHAMAD FAQIH | G13: MLILIR | H13: 45424 | I13: 9.45 | J13: 78.5 | K13: 3 | R13: 45638 | S13: 9.8 | T13: 78.5 | AA13: 45870 | AB13: 10.19 | AC13: 79.8 | AJ13: 22/1/2025 | AK13: 10.85 | AL13: 80.4 | AS13: 20/2/2025 | AT13: 10.1 | AU13: 82.2 | AV13: =AT13-I13 -> 0.65 | AW13: =AU13-J13 -> 3.7 | AX13: -1.63 | AY13: Normal | AZ13: -1.63 | BA13: Normal | BB13: -1.07 | BC13: Normal | BD13: N | BE13: N | BF13: N | BG13: N | BH13: N | BI13: N
A14: 11 | B14: 3308130706230002 | C14: AHMAD HAIDAR AL FAHRI | D14: L | E14: 45084 | F14: MULIA / ABDUL KHADIK | G14: MANGUNAN 2 | H14: 45424 | I14: 9.8 | J14: 78.8 | K14: 3 | R14: 45638 | S14: 9.75 | T14: 78.8 | AA14: 45870 | AB14: 9.5 | AC14: 79.2 | AJ14: 22/1/2025 | AK14: 10 | AL14: 80.4 | AS14: 20/2/2025 | AT14: 10.15 | AU14: 81 | AV14: =AT14-I14 -> 0.35 | AW14: =AU14-J14 -> 2.2 | AX14: -0.73 | AY14: Normal | AZ14: -2.02 | BA14: Pendek | BB14: 0.73 | BC14: Normal | BD14: N | BE14: N | BF14: N | BG14: N | BH14: N | BI14: N
C17: Kenaikan BB
A24: No | B24: NIK | C24: Nama | D24: JK | E24: Tgl Lahir | F24: BB Lahir | G24: TB Lahir | H24: Nama Ortu | I24: Prov | J24: Kab/Kota | K24: Kec | AJ24: Tanggal Pengukuran | AK24: Berat | AL24: Tinggi | AS24: Cara Ukur | AT24: LiLA | AU24: BB/U | AV24: ZS BB/U | AW24: TB/U | BD24: ZS TB/U | BE24: BB/TB | BF24: ZS BB/TB | BG24: Naik Berat Badan | BH24: PMT Diterima (kg) | BI24: Jml Vit A | BJ24: KPSP | BK24: KIA
A25: 23 | B25: 3308130803210001 | C25: AHMAD AZAM WILDAN SYARIF | D25: L | E25: 44263 | F25: 3.1 | G25: 50 | H25: ISMIAH / SLAMET S | I25: JAWA TENGAH | J25: KAB MAGELANG | K25: KALIANGKRIK | AJ25: 45679 | AK25: 12 | AL25: 93.2 | AS25: Berdiri | AT25: 15 | AU25: Kurang | AV25: -2.36 | AW25: Pendek | BD25: -2.24 | BE25: Normal | BF25: -1.63 | BG25: T | BJ25: - | BK25: -
A26: 17 | B26: 3312210403210002 | C26: ALFINA ZAHRA | D26: P | E26: 44299 | F26: 2.8 | G26: 49 | H26: KARYANI / MUDZAKAR SALIM | I26: JAWA TENGAH | J26: KAB MAGELANG | K26: KALIANGKRIK | AJ26: 45677 | AK26: 11.9 | AL26: 88.5 | AS26: Berdiri | AT26: 16 | AU26: Kurang | AV26: -2.06 | AW26: Pendek | BD26: -3 | BE26: Normal | BF26: -0.35 | BG26: T | BJ26: - | BK26: -
A27: 7 | B27: 3308132404210001 | C27: HAIDAR ABDUL RAZAQ | D27: L | E27: 44310 | F27: 3 | G27: 50 | H27: DANIK ATIKAH / SAIFUL ATIQ | I27: JAWA TENGAH | J27: KAB MAGELANG | K27: KALIANGKRIK | AJ27: 45664 | AK27: 13.1 | AL27: 91.5 | AS27: Berdiri | AT27: 15 | AU27: Berat Badan Normal | AV27: -1.49 | AW27: Pendek | BD27: -2.42 | BE27: Normal | BF27: -0.13 | BG27: N | BJ27: - | BK27: -
A28: 4 | B28: 3308136205210001 | C28: ERNA FITRIANI KUSUKMANINGRUM | D28: P | E28: 44338 | F28: 3.2 | G28: 50 | H28: ANA WIDYA / ERI DWI CAHYONO | I28: JAWA TENGAH | J28: KAB MAGELANG | K28: KALIANGKRIK | AJ28: 45665 | AK28: 12.6 | AL28: 91 | AS28: Berdiri | AT28: 16 | AU28: Berat Badan Normal | AV28: -1.47 | AW28: Pendek | BD28: -2.19 | BE28: Normal | BF28: -0.26 | BG28: N | BJ28: - | BK28: -
A29: 30 | B29: 3371035706210002 | C29: KARINA PUTRI PERTIWI | D29: P | E29: 44364 | F29: 3.2 | G29: 50 | H29: NURUL ROKHIMAH / DIMAS SHOLIK | I29: JAWA TENGAH | J29: KAB MAGELANG | K29: KALIANGKRIK | AJ29: 45680 | AK29: 11 | AL29: 90 | AS29: Berdiri | AT29: 14.5 | AU29: Kurang | AV29: -2.53 | AW29: Pendek | BD29: -2.39 | BE29: Normal | BF29: -1.61 | BG29: T | BJ29: - | BK29: -
A30: 19 | B30: 3308130907210001 | C30: AHMAD NAUFAL AL H | D30: L | E30: 44386 | F30: 3 | G30: 49 | H30: CHOIRUL FAIZAH / IMAM FAUZI | I30: JAWA TENGAH | J30: KAB MAGELANG | K30: KALIANGKRIK | AJ30: 45677 | AK30: 12.25 | AL30: 88 | AS30: Berdiri | AT30: 15 | AU30: Berat Badan Normal | AV30: -1.87 | AW30: Sangat Pendek | BD30: -3.04 | BE30: Normal | BF30: -0.16 | BG30: N | BH30: - | BJ30: - | BK30: -
A31: 8 | B31: 3308136107210002 | C31: LATIFAH PUTRI AZZAHRA | D31: P | E31: 44398 | F31: 3 | G31: 5 | H31: FITRI NUR ASTUTI / ERY CAHYONO | I31: JAWA TENGAH | J31: KAB MAGELANG | K31: KALIANGKRIK | AJ31: 45664 | AK31: 11.4 | AL31: 88.4 | AS31: Berdiri | AT31: 15 | AU31: Kurang | AV31: -2.1 | AW31: Pendek | BD31: -2.57 | BE31: Normal | BF31: -0.82 | BG31: T | BJ31: - | BK31: -
A32: 24 | B32: 3308134712210001 | C32: INDIRA QOTRUN NADA | D32: P | E32: 44537 | F32: 3 | G32: 49 | H32: KARIMAH / M. HABIB | I32: JAWA TENGAH | J32: KAB MAGELANG | K32: KALIANGKRIK | AJ32: 45679 | AK32: 11.4 | AL32: 88 | AS32: Berdiri | AT32: 16 | AU32: Berat Badan Normal | AV32: -1.71 | AW32: Pendek | BD32: -2.09 | BE32: Normal | BF32: -0.72 | BG32: T | BH32: - | BJ32: - | BK32: -
A33: 9 | B33: 3308132102220002 | C33: FARREL DWI SAPUTRA | D33: L | E33: 44613 | F33: 3.2 | G33: 50 | H33: IKA KHUSNUL / DWI ANJAR SUKOCO | I33: JAWA TENGAH | J33: KAB MAGELANG | K33: KALIANGKRIK | AJ33: 45664 | AK33: 11 | AL33: 84.4 | AS33: Berdiri | AT33: 15 | AU33: Kurang | AV33: -2.07 | AW33: Pendek | BD33: -2.94 | BE33: Normal | BF33: -0.57 | BG33: T | BJ33: - | BK33: -
A34: 10 | B34: 3308216602200003 | C34: SEZAN AQILA WIBOWO | D34: P | E34: 44620 | F34: 3.2 | G34: 50 | H34: SUSIYANTI / EDI WIBOWO | I34: JAWA TENGAH | J34: KAB MAGELANG | K34: KALIANGKRIK | AJ34: 45664 | AK34: 10.9 | AL34: 84.5 | AS34: Berdiri | AT34: 14 | AU34: Berat Badan Normal | AV34: -1.75 | AW34: Pendek | BD34: -2.51 | BE34: Normal | BF34: -0.38 | BG34: N | BH34: - | BJ34: - | BK34: -
A35: 1 | B35: 3308135106220001 | C35: ANINDIYA DIAUROHMAH | D35: P | E35: 44723 | F35: 2.5 | G35: 47 | H35: HARTANTI / M. ZAENURI | I35: JAWA TENGAH | J35: KAB MAGELANG | K35: KALIANGKRIK | AJ35: 45663 | AK35: 8.1 | AL35: 82 | AS35: Berdiri | AT35: 13 | AU35: Sangat Kurang | AV35: -3.82 | AW35: Pendek | BD35: -2.62 | BE35: Gizi Buruk | BF35: -3.25 | BG35: T | BJ35: - | BK35: -
A36: 25 | B36: 3308134207220001 | C36: RACHEL NADHIRA AL MAHIRA | D36: P | E36: 44744 | F36: 3.2 | G36: 50 | H36: DEWI PUTRI GUMELAR / ABDUL WAHID | I36: JAWA TENGAH | J36: KAB MAGELANG | K36: KALIANGKRIK | AJ36: 45679 | AK36: 11.7 | AL36: 84 | AS36: Berdiri | AT36: 17 | AU36: Berat Badan Normal | AV36: -0.75 | AW36: Pendek | BD36: -2.03 | BE36: Normal | BF36: 0.54 | BG36: N | BJ36: - | BK36: -
A37: 16 | B37: 3308134508220001 | C37: ARSILA ALYA N. S. P | D37: P | E37: 44778 | F37: 3 | G37: 49 | H37: ARIS / NUR HIDAYAH | I37: JAWA TENGAH | J37: KAB MAGELANG | K37: KALIANGKRIK | AJ37: 45672 | AK37: 9.7 | AL37: 83 | AS37: Berdiri | AT37: 15 | AU37: Kurang | AV37: -2.16 | AW37: Pendek | BD37: -2.05 | BE37: Normal | BF37: -1.35 | BG37: N | BJ37: - | BK37: -
A38: 11 | B38: 3308133112220010 | C38: ARIQ RAYYAN ABIZAR | D38: L | E38: 44888 | F38: 3 | G38: 48 | H38: SULISTYANINGSIH | I38: JAWA TENGAH | J38: KAB MAGELANG | K38: KALIANGKRIK | AJ38: 45664 | AK38: 10.3 | AL38: 80.9 | AS38: Berdiri | AT38: 15 | AU38: Berat Badan Normal | AV38: -1.65 | AW38: Pendek | BD38: -2.38 | BE38: Normal | BF38: -0.52 | BG38: T | BH38: - | BJ38: - | BK38: -
A39: 26 | B39: 3308136208850006 | C39: M RIZKI MUBAROK | D39: L | E39: 44973 | F39: 2.8 | G39: 47 | H39: WAHYUNI / NUR CHOLIS | I39: JAWA TENGAH | J39: KAB MAGELANG | K39: KALIANGKRIK | AJ39: 45673 | AK39: 8 | AL39: 76 | AS39: Terlentang | AT39: 14 | AU39: Sangat Kurang | AV39: -3.61 | AW39: Sangat Pendek | BD39: -3.88 | BE39: Gizi Kurang | BF39: -2.4 | BG39: T | BJ39: - | BK39: -
A40: 21 | B40: 3308125004010005 | C40: KHOLIFATUR FAKIH MUAMAR | D40: L | E40: 44975 | F40: 3.5 | G40: 52 | H40: ANIFA DAMAYANTI / A FAUZI | I40: JAWA TENGAH | J40: KAB MAGELANG | K40: KALIANGKRIK | AJ40: 45677 | AK40: 9.3 | AL40: 80 | AS40: Terlentang | AT40: 13 | AU40: Kurang | AV40: -2.22 | AW40: Pendek | BD40: -2.33 | BE40: Normal | BF40: -1.43 | BG40: T | BJ40: - | BK40: -
A41: 18 | B41: 3308166302940001 | C41: ALINA MAHYRA | D41: P | E41: 44998 | F41: 2.8 | G41: 49 | H41: MARYANAH/NUR HADI | I41: JAWA TENGAH | J41: KAB MAGELANG | K41: KALIANGKRIK | AJ41: 45677 | AK41: 8.2 | AL41: 76 | AS41: Terlentang | AT41: 14 | AU41: Kurang | AV41: -2.58 | AW41: Pendek | BD41: -2.83 | BE41: Normal | BF41: -1.48 | BG41: T | BJ41: - | BK41: -
A42: 29 | B42: 3308132403230002 | C42: ABYAN RAMADHANI | D42: L | E42: 45009 | F42: 2.8 | G42: 49 | H42: TUGIYATNI | I42: JAWA TENGAH | J42: KAB MAGELANG | K42: KALIANGKRIK | AJ42: 45680 | AK42: 9.2 | AL42: 79.7 | AS42: Terlentang | AT42: 13.5 | AU42: Kurang | AV42: -2.17 | AW42: Pendek | BD42: -2.18 | BE42: Normal | BF42: -1.5 | BG42: N | BJ42: - | BK42: -
A43: 12 | B43: 3308130305230001 | C43: MUHAMMAD ADE ARSYAD | D43: L | E43: 45049 | F43: 2.8 | G43: 49 | H43: PATIMAH / MUHAMAD FAQIH | I43: JAWA TENGAH | J43: KAB MAGELANG | K43: KALIANGKRIK | AJ43: 45664 | AK43: 10.5 | AL43: 78 | AS43: Terlentang | AT43: 15 | AU43: Berat Badan Normal | AV43: -0.72 | AW43: Pendek | BD43: -2.26 | BE43: Normal | BF43: 0.48 | BG43: N | BJ43: - | BK43: -
A44: 6 | B44: 3308133007230001 | C44: DAFFA KHAFID IRSYAD | D44: L | E44: 45137 | F44: 3 | G44: 47 | H44: siti sariyatun / m susilo | I44: JAWA TENGAH | J44: KAB MAGELANG | K44: KALIANGKRIK | AJ44: 45670 | AK44: 9.6 | AL44: 74 | AS44: Berdiri | AT44: 14.5 | AU44: Berat Badan Normal | AV44: -1.09 | AW44: Pendek | BD44: -2.65 | BE44: Normal | BF44: 0.2 | BG44: N | BJ44: - | BK44: -
A45: 15 | B45: 3308130808230002 | C45: M. MUDZAFFAR AL JIHAD | D45: L | E45: 45146 | F45: 3.2 | G45: 50 | H45: UMI ZULIKA / ANDRI | I45: JAWA TENGAH | J45: KAB MAGELANG | K45: KALIANGKRIK | AJ45: 45666 | AK45: 10.3 | AL45: 75 | AS45: Terlentang | AT45: 17 | AU45: Berat Badan Normal | AV45: -0.39 | AW45: Pendek | BD45: -2.4 | BE45: Normal | BF45: 0.96 | BG45: N | BH45: - | BJ45: - | BK45: -
A46: 20 | B46: 3308131009230001 | C46: FALEYTEHAN SETYAKI SALAM | D46: L | E46: 45179 | F46: 2.8 | G46: 49 | H46: MURNIYATUN / ABDUL SALAM | I46: JAWA TENGAH | J46: KAB MAGELANG | K46: KALIANGKRIK | AJ46: 45677 | AK46: 9.1 | AL46: 74 | AS46: Terlentang | AT46: 14 | AU46: Berat Badan Normal | AV46: -1.38 | AW46: Pendek | BD46: -2.53 | BE46: Normal | BF46: -0.26 | BG46: N | BJ46: - | BK46: -
A47: 2 | B47: 3308401109239769 | C47: M FARIHUNNAJA | D47: L | E47: 45180 | F47: 3.2 | G47: 48 | H47: ISTIYATI | I47: JAWA TENGAH | J47: KAB MAGELANG | K47: KALIANGKRIK | AJ47: 45663 | AK47: 8.5 | AL47: 74 | AS47: Terlentang | AT47: 14 | AU47: Berat Badan Normal | AV47: -1.9 | AW47: Pendek | BD47: -2.36 | BE47: Normal | BF47: -1.1 | BG47: N | BJ47: - | BK47: -
A48: 3 | B48: 3308406310239121 | C48: CHAYRA FAYYOLA NADHIFA | D48: P | E48: 45222 | F48: 3 | G48: 47 | H48: ABDUL KHAMID/RINAWATI | I48: JAWA TENGAH | J48: KAB MAGELANG | K48: KALIANGKRIK | AJ48: 45663 | AK48: 7.8 | AL48: 71 | AS48: Terlentang | AT48: 13 | AU48: Berat Badan Normal | AV48: -1.63 | AW48: Pendek | BD48: -2.19 | BE48: Normal | BF48: -0.78 | BG48: N | BJ48: - | BK48: -
...

Sheet TEMANGGUNG
A1: DATA BALITA MENDAPAT BANTUAN SUSU PKMK
A2: DESA TEMANGGUNG
A3: No | B3: NIK | C3: Nama | D3: JK | E3: Tgl Lahir | F3: Nama Ortu | G3: Alamat | H3: Tanggal Pemberian | I3: Berat | J3: Tinggi | K3: Z-Score BB/U | L3: BB/U | M3: Z-Score TB/U | N3: TB/U | O3: Z-Score BB/TB | P3: BB/TB | Q3: Tanggal Pemberian | R3: Berat | S3: Tinggi | T3: Z-Score BB/U | U3: BB/U | V3: Z-Score TB/U | W3: TB/U | X3: Z-Score BB/TB | Y3: BB/TB | Z3: Tanggal Pemberian | AA3: Berat | AB3: Tinggi | AC3: Z-Score BB/U | AD3: BB/U | AE3: Z-Score TB/U | AF3: TB/U | AG3: Z-Score BB/TB | AH3: BB/TB | AI3: Tanggal Pemberian | AJ3: Berat | AK3: Tinggi | AL3: Z-Score BB/U | AM3: BB/U | AN3: Z-Score TB/U | AO3: TB/U | AP3: Z-Score BB/TB | AQ3: BB/TB | AR3: Tanggal Pemberian | AS3: Berat | AT3: Tinggi | AU3: Z-Score BB/U | AV3: BB/U | AW3: Z-Score TB/U | AX3: TB/U | AY3: Z-Score BB/TB | AZ3: BB/TB | BA3: Tanggal Pemberian | BB3: Berat | BC3: Tinggi | BD3: Z-Score BB/U | BE3: BB/U | BF3: Z-Score TB/U | BG3: TB/U | BH3: Z-Score BB/TB | BI3: BB/TB
A4: 1 | B4: 3308135906210001 | C4: MAZAYA HIKMAH N | D4: P | E4: 45190 | F4: TIA ASTUTI/SIGIT PRASETYO | G4: BUTUH | H4: 45424 | I4: 7.125 | J4: 68.5 | Q4: 45638 | R4: 7.08 | S4: 69.5 | Z4: 45870 | AA4: 7.28 | AB4: 70.5 | AI4: 22/1/2025 | AJ4: 7.4 | AK4: 70.5 | AR4: 45779 | AS4: 7.33 | AT4: 70.6 | AU4: -3.7 | AV4: BB Sgt krg | AW4: -4.82 | AX4: Sgt pendek | AY4: -1.38 | AZ4: Normal | BA4: 20/2/2025 | BB4: 7.49 | BC4: 71.2 | BD4: -3.54 | BE4: BB Sgt krg | BF4: -4.63 | BG4: Sgt pendek | BH4: -1.3 | BI4: Normal
A5: 2 | B5: 3308135801230002 | C5: QANITA RIZQA MAISARAH | D5: P | E5: 44944 | F5: ARIFIN/SAHMI | G5: KRAJAN | H5: 45424 | I5: 7.8 | J5: 77.1 | Q5: 45638 | R5: 7.82 | S5: 77.2 | Z5: 45870 | AA5: 77.5 | AB5: 8.55 | AI5: 22/1/2025 | AJ5: 8.54 | AK5: 77.5 | AR5: 45779 | BA5: 20/2/2025
A6: 3 | B6: 3308400912234140 | C6: MUHAMAD SIDQI AFTAN | D6: L | E6: 45269 | F6: Mira fatmawati/sri anggono | G6: MARON | H6: 45455 | I6: 7.6 | J6: 69.1 | Q6: 45638 | R6: 7.6 | S6: 69 | Z6: 45870 | AA6: 8.1 | AB6: 71 | AI6: 22/1/2025 | AJ6: 7.82 | AK6: 71.4 | AR6: 45779 | AS6: 8.45 | AT6: 71.9 | AU6: -0.85 | AV6: Normal | AW6: -1.64 | AX6: Normal | AY6: -0.13 | AZ6: Normal | BA6: 20/2/2025 | BB6: 8.07 | BC6: 72.2 | BD6: 0.72 | BE6: Normal | BF6: -1.53 | BG6: Normal | BH6: -0.72 | BI6: Normal
A7: 4 | B7: 3308132212230001 | C7: M. HAFIZ AL BAIHAQI | D7: L | E7: 45282 | F7: ISMAIL/TAMBAH SUMINI | G7: PUTIHAN | H7: 45424 | I7: 8.9 | J7: 69.5 | Q7: 45638 | R7: 8.8 | S7: 70.9 | Z7: 45870 | AA7: 8.9 | AB7: 71.1 | AI7: 22/1/2025 | AJ7: 9.1 | AK7: 72 | AR7: 45779 | BA7: 20/2/2025 | BB7: 9 | BC7: 73.5 | BD7: -2.21 | BF7: -4.44 | BG7: Sgt pendek | BH7: -0.26 | BI7: Normal
A8: 5 | B8: 3308406301242575 | C8: M. KENAN ADITAMA | D8: P | E8: 45314 | F8: ROSO/NURGAENI | G8: PUTIHAN | H8: 45424 | I8: 7.52 | J8: 66 | Q8: 45638 | R8: 7.6 | S8: 68.8 | Z8: 45870 | AA8: 8.5 | AB8: 68.4 | AI8: 22/1/2025 | AJ8: 8.3 | AK8: 69 | AR8: 45779 | AS8: 8.5 | AT8: 69.4 | AU8: -1.55 | AV8: Normal | AW8: -3.47 | AX8: Sgt pendek | AY8: 0.31 | AZ8: Normal | BA8: 20/2/2025 | BB8: 8.6 | BC8: 71 | BD8: -1.44 | BE8: Normal | BF8: -2.82 | BG8: Pendek | BH8: -0.07 | BI8: Normal
A9: 6 | B9: 3308130701230002 | C9: AZKA NUR HAFIS | D9: L | E9: 44933 | F9: MUHAMMAD YASIN/HARNI | G9: WARANGAN | H9: 45424 | I9: 8.49 | J9: 76.9 | Q9: 45638 | R9: 8.57 | S9: 75.3 | Z9: 45870 | AA9: 8.9 | AB9: 77.9 | AI9: 22/1/2025 | AJ9: 9.03 | AK9: 78.3 | AR9: 45779 | AS9: 9.3 | AT9: 77 | AU9: -2.47 | AV9: BB Krg | AW9: -3.51 | AX9: Sgt pendek | AY9: -0.92 | AZ9: Normal | BA9: 20/2/2025 | BB9: 9.2 | BC9: 77 | BD9: -2.57 | BE9: BB Krg | BF9: -3.51 | BG9: Pendek | BH9: -1.05 | BI9: Normal
A10: 7 | B10: 3308134802220003 | C10: SALSA FEBRIANA | D10: P | E10: 44600 | F10: Rito-sujiyah | G10: Maron | H10: 45424 | I10: 10.1 | J10: 82.1 | Q10: 14/12/2024 | R10: 10 | S10: 82.4 | Z10: 45870 | AA10: 10 | AB10: 83 | AI10: 22/1/2025 | AJ10: 10.4 | AK10: 83.2 | AR10: 45779 | AS10: 10.5 | AT10: 83.5 | AU10: -2.59 | AV10: BB Krg | AW10: -3.38 | AX10: Sgt pendek | AY10: -0.92 | AZ10: Normal | BA10: 20/2/2025 | BB10: 10.5 | BC10: 83.7 | BD10: -2.59 | BE10: BB Krg | BF10: -3.33 | BG10: Sgt pendek | BH10: -0.97 | BI10: Normal
A11: 8 | B11: 3308406002225385 | C11: AZKIA MUNA | D11: P | E11: 44612 | F11: Turam-srenti | G11: Maron | H11: 45424 | I11: 9.4 | J11: 80.6 | Q11: 45638 | R11: 9.5 | S11: 80.6 | Z11: 45870 | AA11: 9.9 | AB11: 81.5 | AI11: 22/1/2025 | AJ11: 9.03 | AK11: 78.3 | AR11: 45779 | AS11: 9.7 | AT11: 82.2 | AU11: -0.76 | AV11: Normal | AW11: -0.72 | AX11: Normal | AY11: -0.57 | AZ11: Normal | BA11: 20/2/2025 | BB11: 12.5 | BC11: 92 | BD11: -0.76 | BE11: Normal | BF11: -0.72 | BG11: Normal | BH11: -0.57 | BI11: Normal
A12: 9 | B12: 3308132804220003 | C12: FARA SHAKILA | D12: P | E12: 44679 | F12: INTO - ASTRINAH | G12: MARON | H12: 45424 | I12: 10.45 | J12: 83.1 | Q12: 45638 | R12: 10.5 | S12: 83.2 | Z12: 45870 | AA12: 10.5 | AB12: 83.6 | AI12: 22/1/2025 | AJ12: 10.8 | AK12: 84.8 | AR12: 45779 | AS12: 10.9 | AT12: 84.8 | AU12: -0.45 | AV12: Normal | AW12: -2.27 | AX12: Pendek | AY12: -0.45 | AZ12: Normal | BA12: 20/2/2025 | BB12: 10.8 | BC12: 84.9 | BD12: -1.71 | BE12: Normal | BF12: -2.24 | BG12: Pendek | BH12: -0.58 | BI12: Normal
A13: 10 | B13: 3308132706210001 | C13: AZKA HANIF | D13: L | E13: 44374 | F13: SUKIMIN /HARMI | G13: BUTUH | H13: 45424 | I13: 11.8 | J13: 90.4 | Q13: 45638 | R13: 12.3 | S13: 90.7 | Z13: 45870 | AA13: 12.6 | AB13: 91.4 | AI13: 22/1/2025 | AJ13: 12.6 | AK13: 92 | AR13: 45779 | AS13: 12.5 | AT13: 92 | AU13: -0.83 | AV13: Normal | AW13: -2.15 | AX13: Pendek | AY13: 0.83 | AZ13: Normal | BA13: 20/2/2025
A14: 11 | B14: 3308136912210002 | C14: DYAN AURELLIA CAHYANI | D14: P | E14: 44559 | F14: MUKIT/MURTIYANI | G14: GEMBONGAN | H14: 45424 | I14: 10.55 | J14: 81.9 | Q14: 45638 | R14: 11.1 | S14: 83.3 | Z14: 45870 | AA14: 11.2 | AB14: 83.6 | AI14: 22/1/2025 | AJ14: 11.2 | AK14: 84.5 | AR14: 45779 | AS14: 11.8 | AT14: 84.5 | AU14: -1.97 | AV14: Normal | AW14: -3.74 | AX14: Sgt pendek | AY14: 0.51 | AZ14: Normal | BA14: 20/2/2025 | BB14: 11.6 | BC14: 85.1 | BD14: -2.11 | BE14: BB Krg | BF14: -3.59 | BG14: Sgt pendek | BH14: 0.18 | BI14: Normal
A15: 12 | B15: 3308135305210001 | C15: VANIA SAFITRI | D15: P | E15: 44329 | F15: MUNTOLIB/SOPIYAH | G15: BUTUH | H15: 45424 | I15: 11.05 | J15: 86.2 | Q15: 45638 | R15: 11.2 | S15: 86.8 | Z15: 45870 | AA15: 87.8 | AB15: 11.3 | AI15: 22/1/2025 | AJ15: 11.6 | AK15: 89.1 | AR15: 45779 | AS15: 11.6 | AT15: 89.1 | AU15: -2.23 | AV15: BB Krg | AW15: -2.8 | AX15: Pendek | AY15: -0.78 | AZ15: Normal | BA15: 20/2/2025 | BB15: 11.5 | BC15: 88.7 | BD15: -2.18 | BE15: BB Krg | BF15: -2.72 | BG15: Pendek | BH15: -0.79 | BI15: Normal
A16: 13 | B16: 3308401508234420 | C16: AHZAM ALFARIZQI | D16: L | E16: 45153 | F16: MUSLIKIN/SLAMET SAROAH | G16: BUTUH | H16: 45424 | I16: 7.85 | J16: 72.2 | Q16: 45638 | R16: 8.2 | S16: 74 | Z16: 45870 | AA16: 8.14 | AB16: 73.7 | AI16: 22/1/2025 | AJ16: 8.75 | AK16: 73 | AR16: 45779 | AS16: 8.13 | AT16: 73 | AU16: -2.62 | AV16: BB Krg | AW16: -3.36 | AX16: Sgt pendek | AY16: -1.37 | AZ16: Normal | BA16: 20/2/2025 | BB16: 8.2 | BC16: 74.8 | BD16: -2.54 | BE16: BB Krg | BF16: -2.68 | BG16: Pendek | BH16: -1.77 | BI16: Normal
A17: 14 | B17: 3308131107230001 | C17: ZAZAN ARAFIQ | D17: L | E17: 45118 | F17: YAHYA/YAHMI | G17: BUTUH | H17: 45424 | I17: 9.6 | J17: 74 | Q17: 45638 | R17: 9.1 | S17: 74.2 | Z17: 45870 | AA17: 9.5 | AB17: 75.6 | AI17: 22/1/2025 | AJ17: 9.36 | AK17: 76.5 | AR17: 45779 | AS17: 9.6 | AT17: 76.5 | AU17: -1.04 | AV17: Normal | AW17: -1.86 | AX17: Normal | AY17: -0.24 | AZ17: Normal | BA17: 20/2/2025 | BB17: 9.7 | BC17: 77 | BD17: -1.04 | BE17: Normal | BF17: -1.86 | BG17: Pendek | BH17: -0.24 | BI17: Normal
A18: 15 | B18: 3308134305230003 | C18: ALVIA NUR HAFIZAH | D18: P | E18: 45049 | F18: HAMAM-ATUN | G18: BUTUH | H18: 45424 | I18: 7.05 | J18: 73.5 | Q18: 45638 | R18: 8.1 | S18: 74.9 | Z18: 45870 | AA18: 8.1 | AB18: 73.6 | AI18: 22/1/2025 | AJ18: 8.801 | AK18: 75 | AR18: 45779 | AS18: 8.75 | AT18: 76 | AU18: -1.83 | AV18: Normal | AW18: -2.54 | AX18: Pendek | AY18: -0.73 | AZ18: Normal | BA18: 20/2/2025 | BB18: 8.67 | BC18: 76.6 | BD18: -1.91 | BE18: Normal | BF18: -2.35 | BG18: Pendek | BH18: -0.97 | BI18: Normal
A19: 16 | B19: 3308132402230001 | C19: ELVANO KEENAN ALFARISKI | D19: L | E19: 44981 | F19: DAHNI-WANTO | G19: BUTUH | H19: 45424 | I19: 8.35 | J19: 77.8 | Q19: 45638 | R19: 9.26 | S19: 78.2 | Z19: 45870 | AA19: 9.4 | AB19: 78 | AI19: 22/1/2025 | AJ19: 9.37 | AK19: 79.2 | AR19: 45779 | AS19: 9.72 | AT19: 80.5 | AU19: -0.99 | AV19: Normal | AW19: -2.25 | AX19: Pendek | AY19: -1.87 | AZ19: Normal | BA19: 20/2/2025 | BB19: 9.99 | BC19: 80.6 | BD19: -1.63 | BE19: Normal | BF19: -2.22 | BG19: Pendek | BH19: -0.67 | BI19: Normal
A20: 17 | B20: 3308403005228021 | C20: RIZKI ALFATAN | D20: L | E20: 44711 | F20: yadi/ supranti | G20: maron | H20: 45424 | I20: 10.35 | J20: 80.5 | Q20: 45638 | R20: 10.5 | S20: 81.2 | Z20: 45870 | AA20: 11 | AB20: 82.2 | AI20: 22/1/2025 | AJ20: 11 | AK20: 82 | AR20: 45779 | BA20: 20/2/2025
A21: 18 | B21: 3308135408220001 | C21: AISYATUN NAJMA QOLBI | D21: P | E21: 44787 | F21: SOBRI S - ROHANTI | G21: MARON | H21: 45424 | I21: 8.65 | J21: 78.3 | Q21: 45638 | R21: 8.9 | S21: 79 | Z21: 45870 | AA21: 8.7 | AB21: 80.2 | AI21: 22/1/2025 | AJ21: 8.9 | AK21: 80.7 | AR21: 45779 | AS21: 8.8 | AT21: 80.1 | AU21: -3.06 | AV21: BB Sgt krg | AW21: -2.96 | AX21: Pendek | AY21: -1.76 | AZ21: Normal | BA21: 20/2/2025
A22: 19 | B22: 3308405609227928 | C22: AFIFAH ZEA AMANDA | D22: P | E22: 44820 | F22: Dahni slamet- komad | G22: Maron | H22: 45424 | I22: 8.9 | J22: 77.5 | Q22: 45638 | R22: 8.7 | S22: 78 | Z22: 45870 | AA22: 8.9 | AB22: 78.2 | AI22: 22/1/2025 | AJ22: 8.9 | AK22: 79 | AR22: 45779 | AS22: 9.2 | AT22: 79 | AU22: -2.53 | AV22: BB Krg | AW22: -3.7 | AX22: Sgt pendek | AY22: -0.98 | AZ22: Normal | BA22: 20/2/2025
A23: 20 | B23: 3308400503239304 | C23: MUHAMAD HASBI AKSAKA | D23: L | E23: 44990 | F23: ROHMAT I/ISYATUN | G23: MARON | H23: 45424 | I23: 9.7 | J23: 77.3 | Q23: 45638 | R23: 9.9 | S23: 77.5 | Z23: 45870 | AA23: 10.3 | AB23: 79.4 | AI23: 22/1/2025 | AR23: 45779 | BA23: 20/2/2025
A24: 21 | B24: 3308406008238651 | C24: KIRANA ALMANIRA HUSNA | D24: P | E24: 45158 | F24: Fendi- Ika | G24: Maron | H24: 45424 | I24: 8.05 | J24: 71.4 | Q24: 45638 | R24: 8.1 | S24: 73.8 | Z24: 45870 | AA24: 8.6 | AB24: 72.4 | AI24: 22/1/2025 | AJ24: 82 | AK24: 73.6 | AR24: 45779 | BA24: 20/2/2025 | BB24: 8.55 | BC24: 75 | BD24: -1.42 | BE24: Normal | BF24: -1.83 | BG24: Normal | BH24: -0.76 | BI24: Normal
A25: 22 | B25: 3308407108234266 | C25: ALINKA INDARI PUTRI | D25: P | E25: 45169 | F25: Roim- Aripah | G25: Maron | H25: 45424 | I25: 7.1 | J25: 69.5 | Q25: 45638 | R25: 6.8 | S25: 69.1
A26: 23 | C26: AKHTAR NADIF | D26: L | E26: 45047 | F26: PARDIYATI | G26: MARON | Z26: 45870 | AA26: 8.8 | AB26: 81.2 | AI26: 22/1/2025 | AJ26: 9.05 | AK26: 81 | AR26: 45779 | AS26: 9.15 | AT26: 79.9 | AU26: -1.45 | AV26: Normal | AW26: -1.29 | AX26: Normal | AY26: -1.09 | AZ26: Normal | BA26: 20/2/2025 | BB26: 9.2 | BC26: 79.9 | BD26: -1.41 | BE26: Normal | BF26: -1.29 | BG26: Normal | BH26: -1.03 | BI26: Normal
A27: 24 | B27: 3308407107222907 | C27: ASNA AZAHRA | D27: P | E27: 44773 | F27: SUMARI-SRIYATI | G27: TEGALSARI | H27: 45424 | I27: 9.5 | J27: 81.3 | Q27: 45638 | R27: 11.6 | S27: 81.4 | Z27: 45870 | AA27: 10.7 | AB27: 83.2 | AI27: 22/1/2025 | AJ27: 10.7 | AK27: 82.9 | AR27: 45779 | AS27: 10.7 | AT27: 83.4 | AU27: -0.24 | AV27: Normal | AW27: 0.32 | AX27: Normal | AY27: -0.48 | AZ27: Normal
A28: 25 | B28: 3308402411221750 | C28: HUSNI AHMAD MUBAROQ | D28: L | E28: 44889 | F28: A NURUDIN-EKA AFRIYANTI | G28: TEGALSARI | H28: 45424 | I28: 8.5 | J28: 81.5 | Q28: 45638 | R28: 9 | S28: 81 | Z28: 45870 | AA28: 9.4 | AB28: 80.9 | AI28: 22/1/2025 | AJ28: 9.7 | AK28: 80.9 | AR28: 45779 | AS28: 10.1 | AT28: 81.9 | AU28: -0.83 | AV28: Normal | AW28: -0.76 | AX28: Normal | AY28: -0.83 | AZ28: Normal | BA28: 20/2/2025 | BB28: 9.7 | BC28: 82.8 | BD28: -1.12 | BE28: Normal | BF28: 0.1 | BG28: Normal | BH28: -1.56 | BI28: Normal
A29: 26 | B29: 3308401207238517 | C29: ASYAR ALI HASBI | D29: L | E29: 45119 | F29: M.ridHo/nurul arifa | G29: Banjaran | H29: 45424 | I29: 8.5 | J29: 73.6 | Q29: 45638 | R29: 8.88 | S29: 75.5 | Z29: 45870 | AA29: 8.82 | AB29: 75.8 | AI29: 22/1/2025 | AZ29: Normal
A30: 27 | B30: 3308135812220001 | C30: DESTA OLIN MAHARANI | D30: P | E30: 44913 | F30: SUTIK/MEIROSA Y | G30: PRANGKOAN. T | H30: 45424 | I30: 9.09 | J30: 75 | Q30: 45638 | R30: 9.325 | S30: 76.1 | Z30: 45870 | AA30: 9.1 | AB30: 75.4 | AI30: 22/1/2025
A31: 28 | B31: 3308406207239260 | C31: ATALIA PUTRI CLARISA | D31: P | E31: 45129 | F31: Agustina lidya/sutari | G31: PRANGKOAN. T | H31: 45424 | I31: 8.84 | J31: 74.5 | Z31: 45870 | AI31: 22/1/2025
A32: 29 | B32: 3308131809230000 | C32: Nurul Huda Alfarizi | D32: P | E32: 18/2022 | F32: Nurhidayah | Z32: 45870 | AA32: 7.8 | AB32: 70.2 | AI32: 22/1/2025 | AJ32: 7.83 | AK32: 72.6 | AR32: 45779 | AS32: 7.85 | AT32: 73.6 | BA32: 20/2/2025 | BB32: 9.98 | BC32: 74.2
A33: 30 | B33: 0408212802 | C33: SAID ALI | D33: L | E33: 44412 | F33: SOBIKIN/NURYANI | G33: PRANGKOAN B | H33: 45424 | I33: 10.45 | J33: 89.1 | Q33: 45638 | R33: 11.1 | S33: 90.6 | Z33: 45870 | AA33: 11.6 | AB33: 90.9 | AI33: 22/1/2025 | AJ33: 12 | AK33: 91.7 | AR33: 45779 | AS33: 11.9 | AT33: 92.7 | AU33: -2.08 | AV33: BB Krg | AW33: -1.82 | AX33: Normal | AY33: -1.62 | AZ33: Normal | BA33: 20/2/2025 | BB33: 12 | BC33: 93.2 | BD33: -2.01 | BE33: BB Krg | BF33: -1.69 | BG33: Normal | BH33: -1.63 | BI33: Normal
A34: 31 | B34: 3308400602234195 | C34: MUHAMMAD ILHAM SAPUTRA | D34: L | E34: 44963 | F34: Sobikan/fatmiyatun | G34: PRANGKOAN B | H34: 45424 | I34: 9.4 | J34: 82.5 | Q34: 45638 | R34: 10.04 | S34: 81 | Z34: 45870 | AA34: 10.06 | AB34: 81.7 | AI34: 22/1/2025 | AJ34: 10.1 | AK34: 84.5 | AR34: 45779 | AS34: 10.22 | AT34: 83.2 | AU34: -3.69 | AV34: BB Sgt krg | AW34: -4.8 | AX34: Sgt pendek | AY34: -1.18 | AZ34: Normal | BA34: 20/2/2025 | BB34: 10.2 | BC34: 83.2 | BD34: -3.7 | BE34: BB Sgt krg | BF34: -4.8 | BG34: Sgt pendek | BH34: -1.2 | BI34: Normal
A35: J U M L A H

Sheet Sheet1
A2: Nomor | B2: Nama | C2: Jenis Kel | D2: Kenaikan BB | E2: Kenaikan BB
A3: 1 | B3: LUSIANA ANISA F | C3: P | D3: ='BALEKERTO '!AV4 -> 2.05 | E3: ='BALEKERTO '!AW4 -> 2.9
A4: 2 | B4: AHMAD AZAM WILDAN | C4: L | D4: ='BALEKERTO '!AV5 -> -0.32 | E4: ='BALEKERTO '!AW5 -> 2.6
A5: 3 | B5: HAIDAR ABDUL RAZAQ | C5: L | D5: ='BALEKERTO '!AV6 -> 0.8 | E5: ='BALEKERTO '!AW6 -> 1.7
A6: 4 | B6: KARINA PUTRI PERTIWI | C6: P | D6: ='BALEKERTO '!AV7 -> 0.55 | E6: ='BALEKERTO '!AW7 -> 1.3
A7: 5 | B7: LATIFAH PUTRI AZZAHRA | C7: P | D7: ='BALEKERTO '!AV8 -> -0.3 | E7: ='BALEKERTO '!AW8 -> 2.1
A8: 6 | B8: KINANTI NUR KHOLIDA | C8: P | D8: ='BALEKERTO '!AV9 -> 1.4 | E8: ='BALEKERTO '!AW9 -> 1.8
A9: 7 | B9: MUHAMMAD FAWWAZ | C9: L | D9: ='BALEKERTO '!AV10 -> 1.05 | E9: ='BALEKERTO '!AW10 -> 2.2
A10: 8 | B10: RAYYAN AZKA PRATAMA | C10: L | D10: ='BALEKERTO '!AV11 -> 1.75 | E10: ='BALEKERTO '!AW11 -> 3.6
A11: 9 | B11: KHOLIFATUR FAKIH M | C11: L | D11: ='BALEKERTO '!AV12 -> 0.05 | E11: ='BALEKERTO '!AW12 -> 2.3
A12: 10 | B12: MUHAMMAD ADE ARSYAD | C12: L | D12: ='BALEKERTO '!AV13 -> 0.65 | E12: ='BALEKERTO '!AW13 -> 3.7
A13: 11 | B13: AHMAD HAIDAR AL FAHRI | C13: L | D13: ='BALEKERTO '!AV14 -> 0.35 | E13: ='BALEKERTO '!AW14 -> 2.2
